Workbook

Sheet Erklärung
B1: Erklärung – Operative Krankenquote
B4: Was muss ich eintragen? (nur 3 Dinge)
B5: 1. Mitarbeiter | C5: Jede Person einmal: Pers.-Nr., Name, Eintritt, ggf. Austritt, Wochenstunden. Bei Austritt nur Datum eintragen, Zeile nie löschen.
B6: 2. Stunden Objekte | C6: Pro Monat je Objekt EINE Zahl: Gesamtstunden aller Mitarbeiter im Objekt (z. B. aus Dienstplan/Zeiterfassung). Wer zwischen den Objekten wechselt, steckt mit seinen Stunden einfach in der jeweiligen Objektsumme.
B7: 3. Krankmeldungen | C7: Nur wenn jemand krank ist: Pers.-Nr. (Auswahlliste), Objekt (wo der MA eingeplant war), Krank von, Krank bis – wie auf der AU. Bis leer lassen, solange die Person noch krank ist. Arbeitstage und Krankstunden werden automatisch berechnet (Mo–Fr ohne Feiertage, × Std./Tag), auch über Monatsgrenzen hinweg.
B8: Wechsel während Krankheit | C8: Muss eine Krankmeldung auf zwei Objekte aufgeteilt werden: zwei Zeilen mit jeweiligem Zeitraum.
B9: Spalte „Prüfung“ | C9: ok = alles richtig; offen (gelb) = noch kein Bis-Datum; rot = Fehler (Pers.-Nr. unbekannt, Objekt fehlt, Bis vor Von, vor Eintritt, nach Austritt).
B11: Einmalig einrichten (Tab Einstellungen)
B12: Grundwerte | C12: Auswertungsjahr, Objektnamen, Ampelgrenzen, Vollzeit-Wochenstunden.
B13: Gesamtstunden mit Krankstunden? | C13: „Nein“ (Standard), wenn in „Stunden Objekte“ nur tatsächlich gearbeitete Stunden stehen. „Ja“, wenn die Stunden aus dem Dienstplan stammen und Krankstunden bereits enthalten sind.
B14: Feiertage | C14: NRW 2026 sind eingetragen. Die Arbeitstage je Monat berechnen sich daraus automatisch.
B16: Die Auswertungen (alles automatisch)
B17: Krankenquote Objekte | C17: Je Monat und Objekt: Gesamtstunden, Krankstunden, Quote, Krankheitstage, Anzahl kranker MA; Liniendiagramm.
B18: Jahreskumulierung | C18: Im Tab „Krankenquote Objekte“ unter der Monatstabelle: Gesamtstunden, Krankstunden und Quote kumuliert von Januar bis zum jeweiligen Monat (je Objekt und gesamt), mit Liniendiagramm.
B19: KQuote Mitarbeiter | C19: Je Person: Sollstunden, Krankstunden je Objekt, Krankheitstage, Anzahl Krankmeldungen, Quote, Rang, Ampel; Kennzahlen, Kuchendiagramm Bewertung, Top 10.
B20: Auswertung Objekte | C20: Jahresvergleich beider Objekte mit Kuchendiagrammen (Krankstunden, Gesamtstunden) und Monatsdiagramm.
B21: Stundenauswertung | C21: Krankstunden je Mitarbeiter und Monat mit Sollstunden und Quote.
B22: Mitarbeiter (Fluktuation) | C22: Eintritte, Austritte, Bestand je Monat, Fluktuationsquote.
B24: Formeln
B25: Krankstunden | C25: Arbeitstage der Krankmeldung × Std./Tag (Wochenstunden ÷ 5).
B26: Quote je Objekt | C26: Krankstunden ÷ (Gesamtstunden + Krankstunden). Bei Einstellung „Ja“: Krankstunden ÷ Gesamtstunden.
B27: Quote je Mitarbeiter | C27: Krankstunden ÷ Sollstunden. Sollstunden = Arbeitstage zwischen Eintritt (frühestens 1.1.) und Austritt bzw. Stichtag × Std./Tag. Wichtig: Für Mitarbeiter gibt es keine Einzelstunden mehr, daher Soll statt Ist.
B28: Ampel | C28: unauffällig ≤ Schwelle 1, auffällig ≤ Schwelle 2, darüber kritisch.
B29: Fluktuationsquote | C29: Austritte ÷ Ø Personalbestand (Jahresbeginn + 12 Monatsenden).
B30: Ausfall VZ-Stellen | C30: Krankstunden ÷ Jahres-Sollstunden einer Vollzeitkraft.
B32: Hinweise
B33: Kapazität | C33: 200 Mitarbeiter, 1000 Krankmeldungen.
B34: Datenschutz | C34: Gesundheitsdaten sind besonders schützenswert (Art. 9 DSGVO). Zugriff nur für Berechtigte, Datei mit Passwort schützen.
B36: Farblegende
B37: 123 | C37: Eingabe (blaue Schrift / gelbes Feld)
B38: 123 | C38: Verknüpfung aus anderem Tab (grün)
B39: 123 | C39: Automatisch berechnet – nicht überschreiben
B40: unauffällig | C40: Ampel grün
B41: auffällig | C41: Ampel gelb / offen
B42: kritisch | C42: Ampel rot / Fehler

Sheet Einstellungen
A1: Einstellungen | G1: → Erklärung
A2: Zentrale Vorgaben – gelbe Felder anpassen. Alle Tabs beziehen sich auf diese Werte.
B3: Auswertungsjahr | C3: 2026 | D3: Jahr, für das alle Auswertungen rechnen.
B4: Name Objekt 1 | C4: Objekt 1 | D4: Erscheint in allen Auswahllisten und Auswertungen.
B5: Name Objekt 2 | C5: Objekt 2
B6: Vollzeit-Wochenstunden | C6: 40 | D6: Für Ausfall in Vollzeitstellen.
B7: Ampel: unauffällig bis | C7: 0.03 | D7: Krankenquote bis zu diesem Wert = grün.
B8: Ampel: auffällig bis | C8: 0.06 | D8: Bis zu diesem Wert = gelb, darüber = rot (kritisch).
B9: Stichtag | C9: =MIN(TODAY(),DATE(C3,12,31)) | D9: Bis zu diesem Tag werden Sollstunden und offene Krankmeldungen (ohne Bis-Datum) gerechnet.
B10: Gesamtstunden enthalten Krankstunden? | C10: Nein | D10: Nein = in „Stunden Objekte“ stehen nur geleistete Stunden. Ja = Krankstunden sind in den Gesamtstunden schon enthalten.
B12: Monat | C12: Arbeitstage (auto) | E12: Feiertag | F12: Datum
B13: Januar | C13: =NETWORKDAYS(DATE($C$3,1,1),DATE($C$3,2,0),$F$13:$F$32) | E13: Neujahr | F13: 46023
B14: Februar | C14: =NETWORKDAYS(DATE($C$3,2,1),DATE($C$3,3,0),$F$13:$F$32) | E14: Karfreitag | F14: 46115
B15: März | C15: =NETWORKDAYS(DATE($C$3,3,1),DATE($C$3,4,0),$F$13:$F$32) | E15: Ostermontag | F15: 46118
B16: April | C16: =NETWORKDAYS(DATE($C$3,4,1),DATE($C$3,5,0),$F$13:$F$32) | E16: Tag der Arbeit | F16: 46143
B17: Mai | C17: =NETWORKDAYS(DATE($C$3,5,1),DATE($C$3,6,0),$F$13:$F$32) | E17: Christi Himmelfahrt | F17: 46156
B18: Juni | C18: =NETWORKDAYS(DATE($C$3,6,1),DATE($C$3,7,0),$F$13:$F$32) | E18: Pfingstmontag | F18: 46167
B19: Juli | C19: =NETWORKDAYS(DATE($C$3,7,1),DATE($C$3,8,0),$F$13:$F$32) | E19: Fronleichnam | F19: 46177
B20: August | C20: =NETWORKDAYS(DATE($C$3,8,1),DATE($C$3,9,0),$F$13:$F$32) | E20: Tag der Deutschen Einheit | F20: 46298
B21: September | C21: =NETWORKDAYS(DATE($C$3,9,1),DATE($C$3,10,0),$F$13:$F$32) | E21: Allerheiligen | F21: 46327
B22: Oktober | C22: =NETWORKDAYS(DATE($C$3,10,1),DATE($C$3,11,0),$F$13:$F$32) | E22: 1. Weihnachtstag | F22: 46381
B23: November | C23: =NETWORKDAYS(DATE($C$3,11,1),DATE($C$3,12,0),$F$13:$F$32) | E23: 2. Weihnachtstag | F23: 46382
B24: Dezember | C24: =NETWORKDAYS(DATE($C$3,12,1),DATE($C$3,13,0),$F$13:$F$32)
B25: Summe | C25: =SUM(C13:C24)
E33: Feiertage NRW 2026 – für ein anderes Jahr/Bundesland anpassen. Arbeitstage = Mo–Fr ohne diese Feiertage.

Sheet Mitarbeiter
A1: Mitarbeiter – Stammdaten & Fluktuation | N1: → Erklärung
A2: Jede Person nur EINMAL eintragen. Bei Austritt Datum eintragen – Zeile NICHT löschen. Neue Mitarbeiter unten anfügen.
J4: Fluktuation im Auswertungsjahr
A5: Pers.-Nr. | B5: Name | C5: Eintritt | D5: Austritt | E5: Wochen- stunden | F5: Std./Tag | G5: Status | H5: Sollstunden bis Stichtag | J5: Monat | K5: Eintritte | L5: Austritte | M5: Bestand Monatsende
A6: 1001 | B6: Mitarbeiter 001 | C6: 46023 | E6: 40 | F6: =IF(E6="","",E6/5) | G6: =IF(B6="","",IF(C6>Einstellungen!$C$9,"künftig",IF(AND(D6<>"",D6<Einstellungen!$C$9),"ausgeschieden","aktiv"))) | H6: =IF(OR(B6="",E6=""),"",MAX(0,NETWORKDAYS(MAX(C6,DATE(Einstellungen!$C$3,1,1)),MIN(IF(D6="",DATE(Einstellungen!$C$3,12,31),D6),Einstellungen!$C$9),Einstellungen!$F$13:$F$32))*F6) | J6: =DATE(Einstellungen!$C$3,1,1)-1 | K6: Bestand Jahresbeginn → | M6: =COUNTIFS($C$6:$C$205,"<="&J6,$D$6:$D$205,">"&J6)+COUNTIFS($C$6:$C$205,"<="&J6,$D$6:$D$205,"")
A7: 1002 | B7: Mitarbeiter 002 | C7: 46023 | E7: 20 | F7: =IF(E7="","",E7/5) | G7: =IF(B7="","",IF(C7>Einstellungen!$C$9,"künftig",IF(AND(D7<>"",D7<Einstellungen!$C$9),"ausgeschieden","aktiv"))) | H7: =IF(OR(B7="",E7=""),"",MAX(0,NETWORKDAYS(MAX(C7,DATE(Einstellungen!$C$3,1,1)),MIN(IF(D7="",DATE(Einstellungen!$C$3,12,31),D7),Einstellungen!$C$9),Einstellungen!$F$13:$F$32))*F7) | J7: =DATE(Einstellungen!$C$3,1,1) | K7: =COUNTIFS($C$6:$C$205,">="&J7,$C$6:$C$205,"<="&DATE(Einstellungen!$C$3,2,0)) | L7: =COUNTIFS($D$6:$D$205,">="&J7,$D$6:$D$205,"<="&DATE(Einstellungen!$C$3,2,0)) | M7: =COUNTIFS($C$6:$C$205,"<="&DATE(Einstellungen!$C$3,2,0),$D$6:$D$205,">"&DATE(Einstellungen!$C$3,2,0))+COUNTIFS($C$6:$C$205,"<="&DATE(Einstellungen!$C$3,2,0),$D$6:$D$205,"")
A8: 1003 | B8: Mitarbeiter 003 | C8: 46023 | D8: 46293 | E8: 40 | F8: =IF(E8="","",E8/5) | G8: =IF(B8="","",IF(C8>Einstellungen!$C$9,"künftig",IF(AND(D8<>"",D8<Einstellungen!$C$9),"ausgeschieden","aktiv"))) | H8: =IF(OR(B8="",E8=""),"",MAX(0,NETWORKDAYS(MAX(C8,DATE(Einstellungen!$C$3,1,1)),MIN(IF(D8="",DATE(Einstellungen!$C$3,12,31),D8),Einstellungen!$C$9),Einstellungen!$F$13:$F$32))*F8) | J8: =DATE(Einstellungen!$C$3,2,1) | K8: =COUNTIFS($C$6:$C$205,">="&J8,$C$6:$C$205,"<="&DATE(Einstellungen!$C$3,3,0)) | L8: =COUNTIFS($D$6:$D$205,">="&J8,$D$6:$D$205,"<="&DATE(Einstellungen!$C$3,3,0)) | M8: =COUNTIFS($C$6:$C$205,"<="&DATE(Einstellungen!$C$3,3,0),$D$6:$D$205,">"&DATE(Einstellungen!$C$3,3,0))+COUNTIFS($C$6:$C$205,"<="&DATE(Einstellungen!$C$3,3,0),$D$6:$D$205,"")
A9: 1004 | B9: Mitarbeiter 004 | C9: 46023 | E9: 40 | F9: =IF(E9="","",E9/5) | G9: =IF(B9="","",IF(C9>Einstellungen!$C$9,"künftig",IF(AND(D9<>"",D9<Einstellungen!$C$9),"ausgeschieden","aktiv"))) | H9: =IF(OR(B9="",E9=""),"",MAX(0,NETWORKDAYS(MAX(C9,DATE(Einstellungen!$C$3,1,1)),MIN(IF(D9="",DATE(Einstellungen!$C$3,12,31),D9),Einstellungen!$C$9),Einstellungen!$F$13:$F$32))*F9) | J9: =DATE(Einstellungen!$C$3,3,1) | K9: =COUNTIFS($C$6:$C$205,">="&J9,$C$6:$C$205,"<="&DATE(Einstellungen!$C$3,4,0)) | L9: =COUNTIFS($D$6:$D$205,">="&J9,$D$6:$D$205,"<="&DATE(Einstellungen!$C$3,4,0)) | M9: =COUNTIFS($C$6:$C$205,"<="&DATE(Einstellungen!$C$3,4,0),$D$6:$D$205,">"&DATE(Einstellungen!$C$3,4,0))+COUNTIFS($C$6:$C$205,"<="&DATE(Einstellungen!$C$3,4,0),$D$6:$D$205,"")
A10: 1005 | B10: Mitarbeiter 005 | C10: 46023 | D10: 46293 | E10: 40 | F10: =IF(E10="","",E10/5) | G10: =IF(B10="","",IF(C10>Einstellungen!$C$9,"künftig",IF(AND(D10<>"",D10<Einstellungen!$C$9),"ausgeschieden","aktiv"))) | H10: =IF(OR(B10="",E10=""),"",MAX(0,NETWORKDAYS(MAX(C10,DATE(Einstellungen!$C$3,1,1)),MIN(IF(D10="",DATE(Einstellungen!$C$3,12,31),D10),Einstellungen!$C$9),Einstellungen!$F$13:$F$32))*F10) | J10: =DATE(Einstellungen!$C$3,4,1) | K10: =COUNTIFS($C$6:$C$205,">="&J10,$C$6:$C$205,"<="&DATE(Einstellungen!$C$3,5,0)) | L10: =COUNTIFS($D$6:$D$205,">="&J10,$D$6:$D$205,"<="&DATE(Einstellungen!$C$3,5,0)) | M10: =COUNTIFS($C$6:$C$205,"<="&DATE(Einstellungen!$C$3,5,0),$D$6:$D$205,">"&DATE(Einstellungen!$C$3,5,0))+COUNTIFS($C$6:$C$205,"<="&DATE(Einstellungen!$C$3,5,0),$D$6:$D$205,"")
A11: 1006 | B11: Mitarbeiter 006 | C11: 46023 | E11: 40 | F11: =IF(E11="","",E11/5) | G11: =IF(B11="","",IF(C11>Einstellungen!$C$9,"künftig",IF(AND(D11<>"",D11<Einstellungen!$C$9),"ausgeschieden","aktiv"))) | H11: =IF(OR(B11="",E11=""),"",MAX(0,NETWORKDAYS(MAX(C11,DATE(Einstellungen!$C$3,1,1)),MIN(IF(D11="",DATE(Einstellungen!$C$3,12,31),D11),Einstellungen!$C$9),Einstellungen!$F$13:$F$32))*F11) | J11: =DATE(Einstellungen!$C$3,5,1) | K11: =COUNTIFS($C$6:$C$205,">="&J11,$C$6:$C$205,"<="&DATE(Einstellungen!$C$3,6,0)) | L11: =COUNTIFS($D$6:$D$205,">="&J11,$D$6:$D$205,"<="&DATE(Einstellungen!$C$3,6,0)) | M11: =COUNTIFS($C$6:$C$205,"<="&DATE(Einstellungen!$C$3,6,0),$D$6:$D$205,">"&DATE(Einstellungen!$C$3,6,0))+COUNTIFS($C$6:$C$205,"<="&DATE(Einstellungen!$C$3,6,0),$D$6:$D$205,"")
A12: 1007 | B12: Mitarbeiter 007 | C12: 46023 | E12: 40 | F12: =IF(E12="","",E12/5) | G12: =IF(B12="","",IF(C12>Einstellungen!$C$9,"künftig",IF(AND(D12<>"",D12<Einstellungen!$C$9),"ausgeschieden","aktiv"))) | H12: =IF(OR(B12="",E12=""),"",MAX(0,NETWORKDAYS(MAX(C12,DATE(Einstellungen!$C$3,1,1)),MIN(IF(D12="",DATE(Einstellungen!$C$3,12,31),D12),Einstellungen!$C$9),Einstellungen!$F$13:$F$32))*F12) | J12: =DATE(Einstellungen!$C$3,6,1) | K12: =COUNTIFS($C$6:$C$205,">="&J12,$C$6:$C$205,"<="&DATE(Einstellungen!$C$3,7,0)) | L12: =COUNTIFS($D$6:$D$205,">="&J12,$D$6:$D$205,"<="&DATE(Einstellungen!$C$3,7,0)) | M12: =COUNTIFS($C$6:$C$205,"<="&DATE(Einstellungen!$C$3,7,0),$D$6:$D$205,">"&DATE(Einstellungen!$C$3,7,0))+COUNTIFS($C$6:$C$205,"<="&DATE(Einstellungen!$C$3,7,0),$D$6:$D$205,"")
A13: 1008 | B13: Mitarbeiter 008 | C13: 46023 | E13: 30 | F13: =IF(E13="","",E13/5) | G13: =IF(B13="","",IF(C13>Einstellungen!$C$9,"künftig",IF(AND(D13<>"",D13<Einstellungen!$C$9),"ausgeschieden","aktiv"))) | H13: =IF(OR(B13="",E13=""),"",MAX(0,NETWORKDAYS(MAX(C13,DATE(Einstellungen!$C$3,1,1)),MIN(IF(D13="",DATE(Einstellungen!$C$3,12,31),D13),Einstellungen!$C$9),Einstellungen!$F$13:$F$32))*F13) | J13: =DATE(Einstellungen!$C$3,7,1) | K13: =COUNTIFS($C$6:$C$205,">="&J13,$C$6:$C$205,"<="&DATE(Einstellungen!$C$3,8,0)) | L13: =COUNTIFS($D$6:$D$205,">="&J13,$D$6:$D$205,"<="&DATE(Einstellungen!$C$3,8,0)) | M13: =COUNTIFS($C$6:$C$205,"<="&DATE(Einstellungen!$C$3,8,0),$D$6:$D$205,">"&DATE(Einstellungen!$C$3,8,0))+COUNTIFS($C$6:$C$205,"<="&DATE(Einstellungen!$C$3,8,0),$D$6:$D$205,"")
A14: 1009 | B14: Mitarbeiter 009 | C14: 46023 | E14: 30 | F14: =IF(E14="","",E14/5) | G14: =IF(B14="","",IF(C14>Einstellungen!$C$9,"künftig",IF(AND(D14<>"",D14<Einstellungen!$C$9),"ausgeschieden","aktiv"))) | H14: =IF(OR(B14="",E14=""),"",MAX(0,NETWORKDAYS(MAX(C14,DATE(Einstellungen!$C$3,1,1)),MIN(IF(D14="",DATE(Einstellungen!$C$3,12,31),D14),Einstellungen!$C$9),Einstellungen!$F$13:$F$32))*F14) | J14: =DATE(Einstellungen!$C$3,8,1) | K14: =COUNTIFS($C$6:$C$205,">="&J14,$C$6:$C$205,"<="&DATE(Einstellungen!$C$3,9,0)) | L14: =COUNTIFS($D$6:$D$205,">="&J14,$D$6:$D$205,"<="&DATE(Einstellungen!$C$3,9,0)) | M14: =COUNTIFS($C$6:$C$205,"<="&DATE(Einstellungen!$C$3,9,0),$D$6:$D$205,">"&DATE(Einstellungen!$C$3,9,0))+COUNTIFS($C$6:$C$205,"<="&DATE(Einstellungen!$C$3,9,0),$D$6:$D$205,"")
A15: 1010 | B15: Mitarbeiter 010 | C15: 46023 | D15: 46109 | E15: 40 | F15: =IF(E15="","",E15/5) | G15: =IF(B15="","",IF(C15>Einstellungen!$C$9,"künftig",IF(AND(D15<>"",D15<Einstellungen!$C$9),"ausgeschieden","aktiv"))) | H15: =IF(OR(B15="",E15=""),"",MAX(0,NETWORKDAYS(MAX(C15,DATE(Einstellungen!$C$3,1,1)),MIN(IF(D15="",DATE(Einstellungen!$C$3,12,31),D15),Einstellungen!$C$9),Einstellungen!$F$13:$F$32))*F15) | J15: =DATE(Einstellungen!$C$3,9,1) | K15: =COUNTIFS($C$6:$C$205,">="&J15,$C$6:$C$205,"<="&DATE(Einstellungen!$C$3,10,0)) | L15: =COUNTIFS($D$6:$D$205,">="&J15,$D$6:$D$205,"<="&DATE(Einstellungen!$C$3,10,0)) | M15: =COUNTIFS($C$6:$C$205,"<="&DATE(Einstellungen!$C$3,10,0),$D$6:$D$205,">"&DATE(Einstellungen!$C$3,10,0))+COUNTIFS($C$6:$C$205,"<="&DATE(Einstellungen!$C$3,10,0),$D$6:$D$205,"")
A16: 1011 | B16: Mitarbeiter 011 | C16: 46023 | E16: 30 | F16: =IF(E16="","",E16/5) | G16: =IF(B16="","",IF(C16>Einstellungen!$C$9,"künftig",IF(AND(D16<>"",D16<Einstellungen!$C$9),"ausgeschieden","aktiv"))) | H16: =IF(OR(B16="",E16=""),"",MAX(0,NETWORKDAYS(MAX(C16,DATE(Einstellungen!$C$3,1,1)),MIN(IF(D16="",DATE(Einstellungen!$C$3,12,31),D16),Einstellungen!$C$9),Einstellungen!$F$13:$F$32))*F16) | J16: =DATE(Einstellungen!$C$3,10,1) | K16: =COUNTIFS($C$6:$C$205,">="&J16,$C$6:$C$205,"<="&DATE(Einstellungen!$C$3,11,0)) | L16: =COUNTIFS($D$6:$D$205,">="&J16,$D$6:$D$205,"<="&DATE(Einstellungen!$C$3,11,0)) | M16: =COUNTIFS($C$6:$C$205,"<="&DATE(Einstellungen!$C$3,11,0),$D$6:$D$205,">"&DATE(Einstellungen!$C$3,11,0))+COUNTIFS($C$6:$C$205,"<="&DATE(Einstellungen!$C$3,11,0),$D$6:$D$205,"")
A17: 1012 | B17: Mitarbeiter 012 | C17: 46023 | D17: 46081 | E17: 40 | F17: =IF(E17="","",E17/5) | G17: =IF(B17="","",IF(C17>Einstellungen!$C$9,"künftig",IF(AND(D17<>"",D17<Einstellungen!$C$9),"ausgeschieden","aktiv"))) | H17: =IF(OR(B17="",E17=""),"",MAX(0,NETWORKDAYS(MAX(C17,DATE(Einstellungen!$C$3,1,1)),MIN(IF(D17="",DATE(Einstellungen!$C$3,12,31),D17),Einstellungen!$C$9),Einstellungen!$F$13:$F$32))*F17) | J17: =DATE(Einstellungen!$C$3,11,1) | K17: =COUNTIFS($C$6:$C$205,">="&J17,$C$6:$C$205,"<="&DATE(Einstellungen!$C$3,12,0)) | L17: =COUNTIFS($D$6:$D$205,">="&J17,$D$6:$D$205,"<="&DATE(Einstellungen!$C$3,12,0)) | M17: =COUNTIFS($C$6:$C$205,"<="&DATE(Einstellungen!$C$3,12,0),$D$6:$D$205,">"&DATE(Einstellungen!$C$3,12,0))+COUNTIFS($C$6:$C$205,"<="&DATE(Einstellungen!$C$3,12,0),$D$6:$D$205,"")
A18: 1013 | B18: Mitarbeiter 013 | C18: 46023 | D18: 46170 | E18: 40 | F18: =IF(E18="","",E18/5) | G18: =IF(B18="","",IF(C18>Einstellungen!$C$9,"künftig",IF(AND(D18<>"",D18<Einstellungen!$C$9),"ausgeschieden","aktiv"))) | H18: =IF(OR(B18="",E18=""),"",MAX(0,NETWORKDAYS(MAX(C18,DATE(Einstellungen!$C$3,1,1)),MIN(IF(D18="",DATE(Einstellungen!$C$3,12,31),D18),Einstellungen!$C$9),Einstellungen!$F$13:$F$32))*F18) | J18: =DATE(Einstellungen!$C$3,12,1) | K18: =COUNTIFS($C$6:$C$205,">="&J18,$C$6:$C$205,"<="&DATE(Einstellungen!$C$3,13,0)) | L18: =COUNTIFS($D$6:$D$205,">="&J18,$D$6:$D$205,"<="&DATE(Einstellungen!$C$3,13,0)) | M18: =COUNTIFS($C$6:$C$205,"<="&DATE(Einstellungen!$C$3,13,0),$D$6:$D$205,">"&DATE(Einstellungen!$C$3,13,0))+COUNTIFS($C$6:$C$205,"<="&DATE(Einstellungen!$C$3,13,0),$D$6:$D$205,"")
A19: 1014 | B19: Mitarbeiter 014 | C19: 46023 | E19: 40 | F19: =IF(E19="","",E19/5) | G19: =IF(B19="","",IF(C19>Einstellungen!$C$9,"künftig",IF(AND(D19<>"",D19<Einstellungen!$C$9),"ausgeschieden","aktiv"))) | H19: =IF(OR(B19="",E19=""),"",MAX(0,NETWORKDAYS(MAX(C19,DATE(Einstellungen!$C$3,1,1)),MIN(IF(D19="",DATE(Einstellungen!$C$3,12,31),D19),Einstellungen!$C$9),Einstellungen!$F$13:$F$32))*F19) | J19: Summe / Ø | K19: =SUM(K7:K18) | L19: =SUM(L7:L18) | M19: =AVERAGE(M6:M18)
A20: 1015 | B20: Mitarbeiter 015 | C20: 46023 | E20: 40 | F20: =IF(E20="","",E20/5) | G20: =IF(B20="","",IF(C20>Einstellungen!$C$9,"künftig",IF(AND(D20<>"",D20<Einstellungen!$C$9),"ausgeschieden","aktiv"))) | H20: =IF(OR(B20="",E20=""),"",MAX(0,NETWORKDAYS(MAX(C20,DATE(Einstellungen!$C$3,1,1)),MIN(IF(D20="",DATE(Einstellungen!$C$3,12,31),D20),Einstellungen!$C$9),Einstellungen!$F$13:$F$32))*F20)
A21: 1016 | B21: Mitarbeiter 016 | C21: 46023 | E21: 40 | F21: =IF(E21="","",E21/5) | G21: =IF(B21="","",IF(C21>Einstellungen!$C$9,"künftig",IF(AND(D21<>"",D21<Einstellungen!$C$9),"ausgeschieden","aktiv"))) | H21: =IF(OR(B21="",E21=""),"",MAX(0,NETWORKDAYS(MAX(C21,DATE(Einstellungen!$C$3,1,1)),MIN(IF(D21="",DATE(Einstellungen!$C$3,12,31),D21),Einstellungen!$C$9),Einstellungen!$F$13:$F$32))*F21) | J21: Fluktuationsquote (BDA) | M21: =IF(M19>0,L19/M19,0) | N21: Austritte ÷ Ø Personalbestand
A22: 1017 | B22: Mitarbeiter 017 | C22: 46023 | D22: 46170 | E22: 30 | F22: =IF(E22="","",E22/5) | G22: =IF(B22="","",IF(C22>Einstellungen!$C$9,"künftig",IF(AND(D22<>"",D22<Einstellungen!$C$9),"ausgeschieden","aktiv"))) | H22: =IF(OR(B22="",E22=""),"",MAX(0,NETWORKDAYS(MAX(C22,DATE(Einstellungen!$C$3,1,1)),MIN(IF(D22="",DATE(Einstellungen!$C$3,12,31),D22),Einstellungen!$C$9),Einstellungen!$F$13:$F$32))*F22) | J22: Aktive Mitarbeiter (Stichtag) | M22: =COUNTIF($G$6:$G$205,"aktiv")
A23: 1018 | B23: Mitarbeiter 018 | C23: 46023 | E23: 40 | F23: =IF(E23="","",E23/5) | G23: =IF(B23="","",IF(C23>Einstellungen!$C$9,"künftig",IF(AND(D23<>"",D23<Einstellungen!$C$9),"ausgeschieden","aktiv"))) | H23: =IF(OR(B23="",E23=""),"",MAX(0,NETWORKDAYS(MAX(C23,DATE(Einstellungen!$C$3,1,1)),MIN(IF(D23="",DATE(Einstellungen!$C$3,12,31),D23),Einstellungen!$C$9),Einstellungen!$F$13:$F$32))*F23) | J23: Ausgeschiedene gesamt | M23: =COUNTIF($G$6:$G$205,"ausgeschieden")
A24: 1019 | B24: Mitarbeiter 019 | C24: 46023 | E24: 40 | F24: =IF(E24="","",E24/5) | G24: =IF(B24="","",IF(C24>Einstellungen!$C$9,"künftig",IF(AND(D24<>"",D24<Einstellungen!$C$9),"ausgeschieden","aktiv"))) | H24: =IF(OR(B24="",E24=""),"",MAX(0,NETWORKDAYS(MAX(C24,DATE(Einstellungen!$C$3,1,1)),MIN(IF(D24="",DATE(Einstellungen!$C$3,12,31),D24),Einstellungen!$C$9),Einstellungen!$F$13:$F$32))*F24)
A25: 1020 | B25: Mitarbeiter 020 | C25: 46023 | E25: 40 | F25: =IF(E25="","",E25/5) | G25: =IF(B25="","",IF(C25>Einstellungen!$C$9,"künftig",IF(AND(D25<>"",D25<Einstellungen!$C$9),"ausgeschieden","aktiv"))) | H25: =IF(OR(B25="",E25=""),"",MAX(0,NETWORKDAYS(MAX(C25,DATE(Einstellungen!$C$3,1,1)),MIN(IF(D25="",DATE(Einstellungen!$C$3,12,31),D25),Einstellungen!$C$9),Einstellungen!$F$13:$F$32))*F25)
A26: 1021 | B26: Mitarbeiter 021 | C26: 46023 | E26: 20 | F26: =IF(E26="","",E26/5) | G26: =IF(B26="","",IF(C26>Einstellungen!$C$9,"künftig",IF(AND(D26<>"",D26<Einstellungen!$C$9),"ausgeschieden","aktiv"))) | H26: =IF(OR(B26="",E26=""),"",MAX(0,NETWORKDAYS(MAX(C26,DATE(Einstellungen!$C$3,1,1)),MIN(IF(D26="",DATE(Einstellungen!$C$3,12,31),D26),Einstellungen!$C$9),Einstellungen!$F$13:$F$32))*F26)
A27: 1022 | B27: Mitarbeiter 022 | C27: 46023 | E27: 20 | F27: =IF(E27="","",E27/5) | G27: =IF(B27="","",IF(C27>Einstellungen!$C$9,"künftig",IF(AND(D27<>"",D27<Einstellungen!$C$9),"ausgeschieden","aktiv"))) | H27: =IF(OR(B27="",E27=""),"",MAX(0,NETWORKDAYS(MAX(C27,DATE(Einstellungen!$C$3,1,1)),MIN(IF(D27="",DATE(Einstellungen!$C$3,12,31),D27),Einstellungen!$C$9),Einstellungen!$F$13:$F$32))*F27)
A28: 1023 | B28: Mitarbeiter 023 | C28: 46023 | E28: 40 | F28: =IF(E28="","",E28/5) | G28: =IF(B28="","",IF(C28>Einstellungen!$C$9,"künftig",IF(AND(D28<>"",D28<Einstellungen!$C$9),"ausgeschieden","aktiv"))) | H28: =IF(OR(B28="",E28=""),"",MAX(0,NETWORKDAYS(MAX(C28,DATE(Einstellungen!$C$3,1,1)),MIN(IF(D28="",DATE(Einstellungen!$C$3,12,31),D28),Einstellungen!$C$9),Einstellungen!$F$13:$F$32))*F28)
A29: 1024 | B29: Mitarbeiter 024 | C29: 46023 | D29: 46231 | E29: 40 | F29: =IF(E29="","",E29/5) | G29: =IF(B29="","",IF(C29>Einstellungen!$C$9,"künftig",IF(AND(D29<>"",D29<Einstellungen!$C$9),"ausgeschieden","aktiv"))) | H29: =IF(OR(B29="",E29=""),"",MAX(0,NETWORKDAYS(MAX(C29,DATE(Einstellungen!$C$3,1,1)),MIN(IF(D29="",DATE(Einstellungen!$C$3,12,31),D29),Einstellungen!$C$9),Einstellungen!$F$13:$F$32))*F29)
A30: 1025 | B30: Mitarbeiter 025 | C30: 46023 | E30: 40 | F30: =IF(E30="","",E30/5) | G30: =IF(B30="","",IF(C30>Einstellungen!$C$9,"künftig",IF(AND(D30<>"",D30<Einstellungen!$C$9),"ausgeschieden","aktiv"))) | H30: =IF(OR(B30="",E30=""),"",MAX(0,NETWORKDAYS(MAX(C30,DATE(Einstellungen!$C$3,1,1)),MIN(IF(D30="",DATE(Einstellungen!$C$3,12,31),D30),Einstellungen!$C$9),Einstellungen!$F$13:$F$32))*F30)
A31: 1026 | B31: Mitarbeiter 026 | C31: 46023 | D31: 46293 | E31: 40 | F31: =IF(E31="","",E31/5) | G31: =IF(B31="","",IF(C31>Einstellungen!$C$9,"künftig",IF(AND(D31<>"",D31<Einstellungen!$C$9),"ausgeschieden","aktiv"))) | H31: =IF(OR(B31="",E31=""),"",MAX(0,NETWORKDAYS(MAX(C31,DATE(Einstellungen!$C$3,1,1)),MIN(IF(D31="",DATE(Einstellungen!$C$3,12,31),D31),Einstellungen!$C$9),Einstellungen!$F$13:$F$32))*F31)
A32: 1027 | B32: Mitarbeiter 027 | C32: 46023 | D32: 46081 | E32: 40 | F32: =IF(E32="","",E32/5) | G32: =IF(B32="","",IF(C32>Einstellungen!$C$9,"künftig",IF(AND(D32<>"",D32<Einstellungen!$C$9),"ausgeschieden","aktiv"))) | H32: =IF(OR(B32="",E32=""),"",MAX(0,NETWORKDAYS(MAX(C32,DATE(Einstellungen!$C$3,1,1)),MIN(IF(D32="",DATE(Einstellungen!$C$3,12,31),D32),Einstellungen!$C$9),Einstellungen!$F$13:$F$32))*F32)
A33: 1028 | B33: Mitarbeiter 028 | C33: 46023 | E33: 40 | F33: =IF(E33="","",E33/5) | G33: =IF(B33="","",IF(C33>Einstellungen!$C$9,"künftig",IF(AND(D33<>"",D33<Einstellungen!$C$9),"ausgeschieden","aktiv"))) | H33: =IF(OR(B33="",E33=""),"",MAX(0,NETWORKDAYS(MAX(C33,DATE(Einstellungen!$C$3,1,1)),MIN(IF(D33="",DATE(Einstellungen!$C$3,12,31),D33),Einstellungen!$C$9),Einstellungen!$F$13:$F$32))*F33)
A34: 1029 | B34: Mitarbeiter 029 | C34: 46023 | E34: 30 | F34: =IF(E34="","",E34/5) | G34: =IF(B34="","",IF(C34>Einstellungen!$C$9,"künftig",IF(AND(D34<>"",D34<Einstellungen!$C$9),"ausgeschieden","aktiv"))) | H34: =IF(OR(B34="",E34=""),"",MAX(0,NETWORKDAYS(MAX(C34,DATE(Einstellungen!$C$3,1,1)),MIN(IF(D34="",DATE(Einstellungen!$C$3,12,31),D34),Einstellungen!$C$9),Einstellungen!$F$13:$F$32))*F34)
A35: 1030 | B35: Mitarbeiter 030 | C35: 46023 | E35: 20 | F35: =IF(E35="","",E35/5) | G35: =IF(B35="","",IF(C35>Einstellungen!$C$9,"künftig",IF(AND(D35<>"",D35<Einstellungen!$C$9),"ausgeschieden","aktiv"))) | H35: =IF(OR(B35="",E35=""),"",MAX(0,NETWORKDAYS(MAX(C35,DATE(Einstellungen!$C$3,1,1)),MIN(IF(D35="",DATE(Einstellungen!$C$3,12,31),D35),Einstellungen!$C$9),Einstellungen!$F$13:$F$32))*F35)
A36: 1031 | B36: Mitarbeiter 031 | C36: 46023 | E36: 30 | F36: =IF(E36="","",E36/5) | G36: =IF(B36="","",IF(C36>Einstellungen!$C$9,"künftig",IF(AND(D36<>"",D36<Einstellungen!$C$9),"ausgeschieden","aktiv"))) | H36: =IF(OR(B36="",E36=""),"",MAX(0,NETWORKDAYS(MAX(C36,DATE(Einstellungen!$C$3,1,1)),MIN(IF(D36="",DATE(Einstellungen!$C$3,12,31),D36),Einstellungen!$C$9),Einstellungen!$F$13:$F$32))*F36)
A37: 1032 | B37: Mitarbeiter 032 | C37: 46023 | D37: 46140 | E37: 20 | F37: =IF(E37="","",E37/5) | G37: =IF(B37="","",IF(C37>Einstellungen!$C$9,"künftig",IF(AND(D37<>"",D37<Einstellungen!$C$9),"ausgeschieden","aktiv"))) | H37: =IF(OR(B37="",E37=""),"",MAX(0,NETWORKDAYS(MAX(C37,DATE(Einstellungen!$C$3,1,1)),MIN(IF(D37="",DATE(Einstellungen!$C$3,12,31),D37),Einstellungen!$C$9),Einstellungen!$F$13:$F$32))*F37)
A38: 1033 | B38: Mitarbeiter 033 | C38: 46023 | E38: 40 | F38: =IF(E38="","",E38/5) | G38: =IF(B38="","",IF(C38>Einstellungen!$C$9,"künftig",IF(AND(D38<>"",D38<Einstellungen!$C$9),"ausgeschieden","aktiv"))) | H38: =IF(OR(B38="",E38=""),"",MAX(0,NETWORKDAYS(MAX(C38,DATE(Einstellungen!$C$3,1,1)),MIN(IF(D38="",DATE(Einstellungen!$C$3,12,31),D38),Einstellungen!$C$9),Einstellungen!$F$13:$F$32))*F38)
A39: 1034 | B39: Mitarbeiter 034 | C39: 46023 | D39: 46170 | E39: 30 | F39: =IF(E39="","",E39/5) | G39: =IF(B39="","",IF(C39>Einstellungen!$C$9,"künftig",IF(AND(D39<>"",D39<Einstellungen!$C$9),"ausgeschieden","aktiv"))) | H39: =IF(OR(B39="",E39=""),"",MAX(0,NETWORKDAYS(MAX(C39,DATE(Einstellungen!$C$3,1,1)),MIN(IF(D39="",DATE(Einstellungen!$C$3,12,31),D39),Einstellungen!$C$9),Einstellungen!$F$13:$F$32))*F39)
A40: 1035 | B40: Mitarbeiter 035 | C40: 46023 | E40: 40 | F40: =IF(E40="","",E40/5) | G40: =IF(B40="","",IF(C40>Einstellungen!$C$9,"künftig",IF(AND(D40<>"",D40<Einstellungen!$C$9),"ausgeschieden","aktiv"))) | H40: =IF(OR(B40="",E40=""),"",MAX(0,NETWORKDAYS(MAX(C40,DATE(Einstellungen!$C$3,1,1)),MIN(IF(D40="",DATE(Einstellungen!$C$3,12,31),D40),Einstellungen!$C$9),Einstellungen!$F$13:$F$32))*F40)
A41: 1036 | B41: Mitarbeiter 036 | C41: 46023 | E41: 40 | F41: =IF(E41="","",E41/5) | G41: =IF(B41="","",IF(C41>Einstellungen!$C$9,"künftig",IF(AND(D41<>"",D41<Einstellungen!$C$9),"ausgeschieden","aktiv"))) | H41: =IF(OR(B41="",E41=""),"",MAX(0,NETWORKDAYS(MAX(C41,DATE(Einstellungen!$C$3,1,1)),MIN(IF(D41="",DATE(Einstellungen!$C$3,12,31),D41),Einstellungen!$C$9),Einstellungen!$F$13:$F$32))*F41)
...

Sheet Stunden Objekte
A1: Gesamtstunden je Objekt und Monat | G1: → Erklärung
A2: Nur die gelben Felder ausfüllen: Summe aller Stunden des Monats je Objekt (z. B. aus Dienstplan/Zeiterfassung). Ob Krankstunden enthalten sind, in den Einstellungen festlegen.
A4: Monat | B4: =Einstellungen!$C$4 | C4: =Einstellungen!$C$5 | D4: Summe
A5: Januar | B5: 3944 | C5: 4764 | D5: =SUM(B5:C5)
A6: Februar | B6: 3973 | C6: 4834 | D6: =SUM(B6:C6)
A7: März | B7: 4264 | C7: 4799 | D7: =SUM(B7:C7)
A8: April | B8: 4125 | C8: 4790 | D8: =SUM(B8:C8)
A9: Mai | B9: 4080 | C9: 4598 | D9: =SUM(B9:C9)
A10: Juni | B10: 4281 | C10: 4713 | D10: =SUM(B10:C10)
A11: Juli | B11: 3950 | C11: 4415 | D11: =SUM(B11:C11)
A12: August | B12: 4186 | C12: 4844 | D12: =SUM(B12:C12)
A13: September | B13: 3983 | C13: 4942 | D13: =SUM(B13:C13)
A14: Oktober | D14: =SUM(B14:C14)
A15: November | D15: =SUM(B15:C15)
A16: Dezember | D16: =SUM(B16:C16)
A17: Jahr | B17: =SUM(B5:B16) | C17: =SUM(C5:C16) | D17: =SUM(D5:D16)

Sheet Krankmeldungen
A1: Krankmeldungen | N1: → Erklärung
A2: Nur bei Krankheit eine Zeile: Pers.-Nr., Objekt, von, bis (wie AU-Bescheinigung). Bis leer = noch krank (zählt bis Stichtag). Arbeitstage (Mo–Fr ohne Feiertage) und Krankstunden rechnet die Datei. Beispiel: 517321 | Wickede | 02.03.2026 | 06.03.2026 → 5 Tage.
A5: Pers.-Nr. | B5: Name (auto) | C5: Objekt | D5: Krank von | E5: Krank bis | F5: Arbeitstage (auto) | G5: Krank- stunden (auto) | H5: Prüfung (auto) | J5: Bis eff. | K5: Std/Tag | L5: Tage Jan | M5: Tage Feb | N5: Tage Mär | O5: Tage Apr | P5: Tage Mai | Q5: Tage Jun | R5: Tage Jul | S5: Tage Aug | T5: Tage Sep | U5: Tage Okt | V5: Tage Nov | W5: Tage Dez | X5: Std Jan | Y5: Std Feb | Z5: Std Mär | AA5: Std Apr | AB5: Std Mai | AC5: Std Jun | AD5: Std Jul | AE5: Std Aug | AF5: Std Sep | AG5: Std Okt | AH5: Std Nov | AI5: Std Dez
A6: 1035 | B6: =IF(A6="","",IFERROR(INDEX(Mitarbeiter!$B$6:$B$205,MATCH($A6,Mitarbeiter!$A$6:$A$205,0)),"?")) | C6: Objekt 2 | D6: 46025 | E6: 46027 | F6: =IF(A6="","",SUM(L6:W6)) | G6: =IF(A6="","",SUM(X6:AI6)) | H6: =IF(A6="","",IF(ISNA(MATCH(A6,Mitarbeiter!$A$6:$A$205,0)),"Pers.-Nr. unbekannt",IF(D6="","Von fehlt",IF(AND(C6<>Einstellungen!$C$4,C6<>Einstellungen!$C$5),"Objekt fehlt",IF(J6<D6,"Bis vor Von",IF(D6<INDEX(Mitarbeiter!$C$6:$C$205,MATCH($A6,Mitarbeiter!$A$6:$A$205,0)),"vor Eintritt",IF(AND(INDEX(Mitarbeiter!$D$6:$D$205,MATCH($A6,Mitarbeiter!$A$6:$A$205,0))<>"",D6>INDEX(Mitarbeiter!$D$6:$D$205,MATCH($A6,Mitarbeiter!$A$6:$A$205,0))),"nach Austritt",IF(E6="","offen","ok")))))))) | J6: =IF(A6="","",IF(E6="",Einstellungen!$C$9,E6)) | K6: =IF(A6="",0,IFERROR(INDEX(Mitarbeiter!$F$6:$F$205,MATCH($A6,Mitarbeiter!$A$6:$A$205,0)),0)) | L6: =IF(OR(A6="",D6=""),0,MAX(0,NETWORKDAYS(MAX(D6,DATE(Einstellungen!$C$3,1,1)),MIN(J6,DATE(Einstellungen!$C$3,2,0)),Einstellungen!$F$13:$F$32))) | M6: =IF(OR(A6="",D6=""),0,MAX(0,NETWORKDAYS(MAX(D6,DATE(Einstellungen!$C$3,2,1)),MIN(J6,DATE(Einstellungen!$C$3,3,0)),Einstellungen!$F$13:$F$32))) | N6: =IF(OR(A6="",D6=""),0,MAX(0,NETWORKDAYS(MAX(D6,DATE(Einstellungen!$C$3,3,1)),MIN(J6,DATE(Einstellungen!$C$3,4,0)),Einstellungen!$F$13:$F$32))) | O6: =IF(OR(A6="",D6=""),0,MAX(0,NETWORKDAYS(MAX(D6,DATE(Einstellungen!$C$3,4,1)),MIN(J6,DATE(Einstellungen!$C$3,5,0)),Einstellungen!$F$13:$F$32))) | P6: =IF(OR(A6="",D6=""),0,MAX(0,NETWORKDAYS(MAX(D6,DATE(Einstellungen!$C$3,5,1)),MIN(J6,DATE(Einstellungen!$C$3,6,0)),Einstellungen!$F$13:$F$32))) | Q6: =IF(OR(A6="",D6=""),0,MAX(0,NETWORKDAYS(MAX(D6,DATE(Einstellungen!$C$3,6,1)),MIN(J6,DATE(Einstellungen!$C$3,7,0)),Einstellungen!$F$13:$F$32))) | R6: =IF(OR(A6="",D6=""),0,MAX(0,NETWORKDAYS(MAX(D6,DATE(Einstellungen!$C$3,7,1)),MIN(J6,DATE(Einstellungen!$C$3,8,0)),Einstellungen!$F$13:$F$32))) | S6: =IF(OR(A6="",D6=""),0,MAX(0,NETWORKDAYS(MAX(D6,DATE(Einstellungen!$C$3,8,1)),MIN(J6,DATE(Einstellungen!$C$3,9,0)),Einstellungen!$F$13:$F$32))) | T6: =IF(OR(A6="",D6=""),0,MAX(0,NETWORKDAYS(MAX(D6,DATE(Einstellungen!$C$3,9,1)),MIN(J6,DATE(Einstellungen!$C$3,10,0)),Einstellungen!$F$13:$F$32))) | U6: =IF(OR(A6="",D6=""),0,MAX(0,NETWORKDAYS(MAX(D6,DATE(Einstellungen!$C$3,10,1)),MIN(J6,DATE(Einstellungen!$C$3,11,0)),Einstellungen!$F$13:$F$32))) | V6: =IF(OR(A6="",D6=""),0,MAX(0,NETWORKDAYS(MAX(D6,DATE(Einstellungen!$C$3,11,1)),MIN(J6,DATE(Einstellungen!$C$3,12,0)),Einstellungen!$F$13:$F$32))) | W6: =IF(OR(A6="",D6=""),0,MAX(0,NETWORKDAYS(MAX(D6,DATE(Einstellungen!$C$3,12,1)),MIN(J6,DATE(Einstellungen!$C$3,13,0)),Einstellungen!$F$13:$F$32))) | X6: =L6*K6 | Y6: =M6*K6 | Z6: =N6*K6 | AA6: =O6*K6 | AB6: =P6*K6 | AC6: =Q6*K6 | AD6: =R6*K6 | AE6: =S6*K6 | AF6: =T6*K6 | AG6: =U6*K6 | AH6: =V6*K6 | AI6: =W6*K6
A7: 1006 | B7: =IF(A7="","",IFERROR(INDEX(Mitarbeiter!$B$6:$B$205,MATCH($A7,Mitarbeiter!$A$6:$A$205,0)),"?")) | C7: Objekt 2 | D7: 46025 | E7: 46026 | F7: =IF(A7="","",SUM(L7:W7)) | G7: =IF(A7="","",SUM(X7:AI7)) | H7: =IF(A7="","",IF(ISNA(MATCH(A7,Mitarbeiter!$A$6:$A$205,0)),"Pers.-Nr. unbekannt",IF(D7="","Von fehlt",IF(AND(C7<>Einstellungen!$C$4,C7<>Einstellungen!$C$5),"Objekt fehlt",IF(J7<D7,"Bis vor Von",IF(D7<INDEX(Mitarbeiter!$C$6:$C$205,MATCH($A7,Mitarbeiter!$A$6:$A$205,0)),"vor Eintritt",IF(AND(INDEX(Mitarbeiter!$D$6:$D$205,MATCH($A7,Mitarbeiter!$A$6:$A$205,0))<>"",D7>INDEX(Mitarbeiter!$D$6:$D$205,MATCH($A7,Mitarbeiter!$A$6:$A$205,0))),"nach Austritt",IF(E7="","offen","ok")))))))) | J7: =IF(A7="","",IF(E7="",Einstellungen!$C$9,E7)) | K7: =IF(A7="",0,IFERROR(INDEX(Mitarbeiter!$F$6:$F$205,MATCH($A7,Mitarbeiter!$A$6:$A$205,0)),0)) | L7: =IF(OR(A7="",D7=""),0,MAX(0,NETWORKDAYS(MAX(D7,DATE(Einstellungen!$C$3,1,1)),MIN(J7,DATE(Einstellungen!$C$3,2,0)),Einstellungen!$F$13:$F$32))) | M7: =IF(OR(A7="",D7=""),0,MAX(0,NETWORKDAYS(MAX(D7,DATE(Einstellungen!$C$3,2,1)),MIN(J7,DATE(Einstellungen!$C$3,3,0)),Einstellungen!$F$13:$F$32))) | N7: =IF(OR(A7="",D7=""),0,MAX(0,NETWORKDAYS(MAX(D7,DATE(Einstellungen!$C$3,3,1)),MIN(J7,DATE(Einstellungen!$C$3,4,0)),Einstellungen!$F$13:$F$32))) | O7: =IF(OR(A7="",D7=""),0,MAX(0,NETWORKDAYS(MAX(D7,DATE(Einstellungen!$C$3,4,1)),MIN(J7,DATE(Einstellungen!$C$3,5,0)),Einstellungen!$F$13:$F$32))) | P7: =IF(OR(A7="",D7=""),0,MAX(0,NETWORKDAYS(MAX(D7,DATE(Einstellungen!$C$3,5,1)),MIN(J7,DATE(Einstellungen!$C$3,6,0)),Einstellungen!$F$13:$F$32))) | Q7: =IF(OR(A7="",D7=""),0,MAX(0,NETWORKDAYS(MAX(D7,DATE(Einstellungen!$C$3,6,1)),MIN(J7,DATE(Einstellungen!$C$3,7,0)),Einstellungen!$F$13:$F$32))) | R7: =IF(OR(A7="",D7=""),0,MAX(0,NETWORKDAYS(MAX(D7,DATE(Einstellungen!$C$3,7,1)),MIN(J7,DATE(Einstellungen!$C$3,8,0)),Einstellungen!$F$13:$F$32))) | S7: =IF(OR(A7="",D7=""),0,MAX(0,NETWORKDAYS(MAX(D7,DATE(Einstellungen!$C$3,8,1)),MIN(J7,DATE(Einstellungen!$C$3,9,0)),Einstellungen!$F$13:$F$32))) | T7: =IF(OR(A7="",D7=""),0,MAX(0,NETWORKDAYS(MAX(D7,DATE(Einstellungen!$C$3,9,1)),MIN(J7,DATE(Einstellungen!$C$3,10,0)),Einstellungen!$F$13:$F$32))) | U7: =IF(OR(A7="",D7=""),0,MAX(0,NETWORKDAYS(MAX(D7,DATE(Einstellungen!$C$3,10,1)),MIN(J7,DATE(Einstellungen!$C$3,11,0)),Einstellungen!$F$13:$F$32))) | V7: =IF(OR(A7="",D7=""),0,MAX(0,NETWORKDAYS(MAX(D7,DATE(Einstellungen!$C$3,11,1)),MIN(J7,DATE(Einstellungen!$C$3,12,0)),Einstellungen!$F$13:$F$32))) | W7: =IF(OR(A7="",D7=""),0,MAX(0,NETWORKDAYS(MAX(D7,DATE(Einstellungen!$C$3,12,1)),MIN(J7,DATE(Einstellungen!$C$3,13,0)),Einstellungen!$F$13:$F$32))) | X7: =L7*K7 | Y7: =M7*K7 | Z7: =N7*K7 | AA7: =O7*K7 | AB7: =P7*K7 | AC7: =Q7*K7 | AD7: =R7*K7 | AE7: =S7*K7 | AF7: =T7*K7 | AG7: =U7*K7 | AH7: =V7*K7 | AI7: =W7*K7
A8: 1002 | B8: =IF(A8="","",IFERROR(INDEX(Mitarbeiter!$B$6:$B$205,MATCH($A8,Mitarbeiter!$A$6:$A$205,0)),"?")) | C8: Objekt 1 | D8: 46026 | E8: 46026 | F8: =IF(A8="","",SUM(L8:W8)) | G8: =IF(A8="","",SUM(X8:AI8)) | H8: =IF(A8="","",IF(ISNA(MATCH(A8,Mitarbeiter!$A$6:$A$205,0)),"Pers.-Nr. unbekannt",IF(D8="","Von fehlt",IF(AND(C8<>Einstellungen!$C$4,C8<>Einstellungen!$C$5),"Objekt fehlt",IF(J8<D8,"Bis vor Von",IF(D8<INDEX(Mitarbeiter!$C$6:$C$205,MATCH($A8,Mitarbeiter!$A$6:$A$205,0)),"vor Eintritt",IF(AND(INDEX(Mitarbeiter!$D$6:$D$205,MATCH($A8,Mitarbeiter!$A$6:$A$205,0))<>"",D8>INDEX(Mitarbeiter!$D$6:$D$205,MATCH($A8,Mitarbeiter!$A$6:$A$205,0))),"nach Austritt",IF(E8="","offen","ok")))))))) | J8: =IF(A8="","",IF(E8="",Einstellungen!$C$9,E8)) | K8: =IF(A8="",0,IFERROR(INDEX(Mitarbeiter!$F$6:$F$205,MATCH($A8,Mitarbeiter!$A$6:$A$205,0)),0)) | L8: =IF(OR(A8="",D8=""),0,MAX(0,NETWORKDAYS(MAX(D8,DATE(Einstellungen!$C$3,1,1)),MIN(J8,DATE(Einstellungen!$C$3,2,0)),Einstellungen!$F$13:$F$32))) | M8: =IF(OR(A8="",D8=""),0,MAX(0,NETWORKDAYS(MAX(D8,DATE(Einstellungen!$C$3,2,1)),MIN(J8,DATE(Einstellungen!$C$3,3,0)),Einstellungen!$F$13:$F$32))) | N8: =IF(OR(A8="",D8=""),0,MAX(0,NETWORKDAYS(MAX(D8,DATE(Einstellungen!$C$3,3,1)),MIN(J8,DATE(Einstellungen!$C$3,4,0)),Einstellungen!$F$13:$F$32))) | O8: =IF(OR(A8="",D8=""),0,MAX(0,NETWORKDAYS(MAX(D8,DATE(Einstellungen!$C$3,4,1)),MIN(J8,DATE(Einstellungen!$C$3,5,0)),Einstellungen!$F$13:$F$32))) | P8: =IF(OR(A8="",D8=""),0,MAX(0,NETWORKDAYS(MAX(D8,DATE(Einstellungen!$C$3,5,1)),MIN(J8,DATE(Einstellungen!$C$3,6,0)),Einstellungen!$F$13:$F$32))) | Q8: =IF(OR(A8="",D8=""),0,MAX(0,NETWORKDAYS(MAX(D8,DATE(Einstellungen!$C$3,6,1)),MIN(J8,DATE(Einstellungen!$C$3,7,0)),Einstellungen!$F$13:$F$32))) | R8: =IF(OR(A8="",D8=""),0,MAX(0,NETWORKDAYS(MAX(D8,DATE(Einstellungen!$C$3,7,1)),MIN(J8,DATE(Einstellungen!$C$3,8,0)),Einstellungen!$F$13:$F$32))) | S8: =IF(OR(A8="",D8=""),0,MAX(0,NETWORKDAYS(MAX(D8,DATE(Einstellungen!$C$3,8,1)),MIN(J8,DATE(Einstellungen!$C$3,9,0)),Einstellungen!$F$13:$F$32))) | T8: =IF(OR(A8="",D8=""),0,MAX(0,NETWORKDAYS(MAX(D8,DATE(Einstellungen!$C$3,9,1)),MIN(J8,DATE(Einstellungen!$C$3,10,0)),Einstellungen!$F$13:$F$32))) | U8: =IF(OR(A8="",D8=""),0,MAX(0,NETWORKDAYS(MAX(D8,DATE(Einstellungen!$C$3,10,1)),MIN(J8,DATE(Einstellungen!$C$3,11,0)),Einstellungen!$F$13:$F$32))) | V8: =IF(OR(A8="",D8=""),0,MAX(0,NETWORKDAYS(MAX(D8,DATE(Einstellungen!$C$3,11,1)),MIN(J8,DATE(Einstellungen!$C$3,12,0)),Einstellungen!$F$13:$F$32))) | W8: =IF(OR(A8="",D8=""),0,MAX(0,NETWORKDAYS(MAX(D8,DATE(Einstellungen!$C$3,12,1)),MIN(J8,DATE(Einstellungen!$C$3,13,0)),Einstellungen!$F$13:$F$32))) | X8: =L8*K8 | Y8: =M8*K8 | Z8: =N8*K8 | AA8: =O8*K8 | AB8: =P8*K8 | AC8: =Q8*K8 | AD8: =R8*K8 | AE8: =S8*K8 | AF8: =T8*K8 | AG8: =U8*K8 | AH8: =V8*K8 | AI8: =W8*K8
A9: 1024 | B9: =IF(A9="","",IFERROR(INDEX(Mitarbeiter!$B$6:$B$205,MATCH($A9,Mitarbeiter!$A$6:$A$205,0)),"?")) | C9: Objekt 2 | D9: 46027 | E9: 46031 | F9: =IF(A9="","",SUM(L9:W9)) | G9: =IF(A9="","",SUM(X9:AI9)) | H9: =IF(A9="","",IF(ISNA(MATCH(A9,Mitarbeiter!$A$6:$A$205,0)),"Pers.-Nr. unbekannt",IF(D9="","Von fehlt",IF(AND(C9<>Einstellungen!$C$4,C9<>Einstellungen!$C$5),"Objekt fehlt",IF(J9<D9,"Bis vor Von",IF(D9<INDEX(Mitarbeiter!$C$6:$C$205,MATCH($A9,Mitarbeiter!$A$6:$A$205,0)),"vor Eintritt",IF(AND(INDEX(Mitarbeiter!$D$6:$D$205,MATCH($A9,Mitarbeiter!$A$6:$A$205,0))<>"",D9>INDEX(Mitarbeiter!$D$6:$D$205,MATCH($A9,Mitarbeiter!$A$6:$A$205,0))),"nach Austritt",IF(E9="","offen","ok")))))))) | J9: =IF(A9="","",IF(E9="",Einstellungen!$C$9,E9)) | K9: =IF(A9="",0,IFERROR(INDEX(Mitarbeiter!$F$6:$F$205,MATCH($A9,Mitarbeiter!$A$6:$A$205,0)),0)) | L9: =IF(OR(A9="",D9=""),0,MAX(0,NETWORKDAYS(MAX(D9,DATE(Einstellungen!$C$3,1,1)),MIN(J9,DATE(Einstellungen!$C$3,2,0)),Einstellungen!$F$13:$F$32))) | M9: =IF(OR(A9="",D9=""),0,MAX(0,NETWORKDAYS(MAX(D9,DATE(Einstellungen!$C$3,2,1)),MIN(J9,DATE(Einstellungen!$C$3,3,0)),Einstellungen!$F$13:$F$32))) | N9: =IF(OR(A9="",D9=""),0,MAX(0,NETWORKDAYS(MAX(D9,DATE(Einstellungen!$C$3,3,1)),MIN(J9,DATE(Einstellungen!$C$3,4,0)),Einstellungen!$F$13:$F$32))) | O9: =IF(OR(A9="",D9=""),0,MAX(0,NETWORKDAYS(MAX(D9,DATE(Einstellungen!$C$3,4,1)),MIN(J9,DATE(Einstellungen!$C$3,5,0)),Einstellungen!$F$13:$F$32))) | P9: =IF(OR(A9="",D9=""),0,MAX(0,NETWORKDAYS(MAX(D9,DATE(Einstellungen!$C$3,5,1)),MIN(J9,DATE(Einstellungen!$C$3,6,0)),Einstellungen!$F$13:$F$32))) | Q9: =IF(OR(A9="",D9=""),0,MAX(0,NETWORKDAYS(MAX(D9,DATE(Einstellungen!$C$3,6,1)),MIN(J9,DATE(Einstellungen!$C$3,7,0)),Einstellungen!$F$13:$F$32))) | R9: =IF(OR(A9="",D9=""),0,MAX(0,NETWORKDAYS(MAX(D9,DATE(Einstellungen!$C$3,7,1)),MIN(J9,DATE(Einstellungen!$C$3,8,0)),Einstellungen!$F$13:$F$32))) | S9: =IF(OR(A9="",D9=""),0,MAX(0,NETWORKDAYS(MAX(D9,DATE(Einstellungen!$C$3,8,1)),MIN(J9,DATE(Einstellungen!$C$3,9,0)),Einstellungen!$F$13:$F$32))) | T9: =IF(OR(A9="",D9=""),0,MAX(0,NETWORKDAYS(MAX(D9,DATE(Einstellungen!$C$3,9,1)),MIN(J9,DATE(Einstellungen!$C$3,10,0)),Einstellungen!$F$13:$F$32))) | U9: =IF(OR(A9="",D9=""),0,MAX(0,NETWORKDAYS(MAX(D9,DATE(Einstellungen!$C$3,10,1)),MIN(J9,DATE(Einstellungen!$C$3,11,0)),Einstellungen!$F$13:$F$32))) | V9: =IF(OR(A9="",D9=""),0,MAX(0,NETWORKDAYS(MAX(D9,DATE(Einstellungen!$C$3,11,1)),MIN(J9,DATE(Einstellungen!$C$3,12,0)),Einstellungen!$F$13:$F$32))) | W9: =IF(OR(A9="",D9=""),0,MAX(0,NETWORKDAYS(MAX(D9,DATE(Einstellungen!$C$3,12,1)),MIN(J9,DATE(Einstellungen!$C$3,13,0)),Einstellungen!$F$13:$F$32))) | X9: =L9*K9 | Y9: =M9*K9 | Z9: =N9*K9 | AA9: =O9*K9 | AB9: =P9*K9 | AC9: =Q9*K9 | AD9: =R9*K9 | AE9: =S9*K9 | AF9: =T9*K9 | AG9: =U9*K9 | AH9: =V9*K9 | AI9: =W9*K9
A10: 1005 | B10: =IF(A10="","",IFERROR(INDEX(Mitarbeiter!$B$6:$B$205,MATCH($A10,Mitarbeiter!$A$6:$A$205,0)),"?")) | C10: Objekt 1 | D10: 46033 | E10: 46046 | F10: =IF(A10="","",SUM(L10:W10)) | G10: =IF(A10="","",SUM(X10:AI10)) | H10: =IF(A10="","",IF(ISNA(MATCH(A10,Mitarbeiter!$A$6:$A$205,0)),"Pers.-Nr. unbekannt",IF(D10="","Von fehlt",IF(AND(C10<>Einstellungen!$C$4,C10<>Einstellungen!$C$5),"Objekt fehlt",IF(J10<D10,"Bis vor Von",IF(D10<INDEX(Mitarbeiter!$C$6:$C$205,MATCH($A10,Mitarbeiter!$A$6:$A$205,0)),"vor Eintritt",IF(AND(INDEX(Mitarbeiter!$D$6:$D$205,MATCH($A10,Mitarbeiter!$A$6:$A$205,0))<>"",D10>INDEX(Mitarbeiter!$D$6:$D$205,MATCH($A10,Mitarbeiter!$A$6:$A$205,0))),"nach Austritt",IF(E10="","offen","ok")))))))) | J10: =IF(A10="","",IF(E10="",Einstellungen!$C$9,E10)) | K10: =IF(A10="",0,IFERROR(INDEX(Mitarbeiter!$F$6:$F$205,MATCH($A10,Mitarbeiter!$A$6:$A$205,0)),0)) | L10: =IF(OR(A10="",D10=""),0,MAX(0,NETWORKDAYS(MAX(D10,DATE(Einstellungen!$C$3,1,1)),MIN(J10,DATE(Einstellungen!$C$3,2,0)),Einstellungen!$F$13:$F$32))) | M10: =IF(OR(A10="",D10=""),0,MAX(0,NETWORKDAYS(MAX(D10,DATE(Einstellungen!$C$3,2,1)),MIN(J10,DATE(Einstellungen!$C$3,3,0)),Einstellungen!$F$13:$F$32))) | N10: =IF(OR(A10="",D10=""),0,MAX(0,NETWORKDAYS(MAX(D10,DATE(Einstellungen!$C$3,3,1)),MIN(J10,DATE(Einstellungen!$C$3,4,0)),Einstellungen!$F$13:$F$32))) | O10: =IF(OR(A10="",D10=""),0,MAX(0,NETWORKDAYS(MAX(D10,DATE(Einstellungen!$C$3,4,1)),MIN(J10,DATE(Einstellungen!$C$3,5,0)),Einstellungen!$F$13:$F$32))) | P10: =IF(OR(A10="",D10=""),0,MAX(0,NETWORKDAYS(MAX(D10,DATE(Einstellungen!$C$3,5,1)),MIN(J10,DATE(Einstellungen!$C$3,6,0)),Einstellungen!$F$13:$F$32))) | Q10: =IF(OR(A10="",D10=""),0,MAX(0,NETWORKDAYS(MAX(D10,DATE(Einstellungen!$C$3,6,1)),MIN(J10,DATE(Einstellungen!$C$3,7,0)),Einstellungen!$F$13:$F$32))) | R10: =IF(OR(A10="",D10=""),0,MAX(0,NETWORKDAYS(MAX(D10,DATE(Einstellungen!$C$3,7,1)),MIN(J10,DATE(Einstellungen!$C$3,8,0)),Einstellungen!$F$13:$F$32))) | S10: =IF(OR(A10="",D10=""),0,MAX(0,NETWORKDAYS(MAX(D10,DATE(Einstellungen!$C$3,8,1)),MIN(J10,DATE(Einstellungen!$C$3,9,0)),Einstellungen!$F$13:$F$32))) | T10: =IF(OR(A10="",D10=""),0,MAX(0,NETWORKDAYS(MAX(D10,DATE(Einstellungen!$C$3,9,1)),MIN(J10,DATE(Einstellungen!$C$3,10,0)),Einstellungen!$F$13:$F$32))) | U10: =IF(OR(A10="",D10=""),0,MAX(0,NETWORKDAYS(MAX(D10,DATE(Einstellungen!$C$3,10,1)),MIN(J10,DATE(Einstellungen!$C$3,11,0)),Einstellungen!$F$13:$F$32))) | V10: =IF(OR(A10="",D10=""),0,MAX(0,NETWORKDAYS(MAX(D10,DATE(Einstellungen!$C$3,11,1)),MIN(J10,DATE(Einstellungen!$C$3,12,0)),Einstellungen!$F$13:$F$32))) | W10: =IF(OR(A10="",D10=""),0,MAX(0,NETWORKDAYS(MAX(D10,DATE(Einstellungen!$C$3,12,1)),MIN(J10,DATE(Einstellungen!$C$3,13,0)),Einstellungen!$F$13:$F$32))) | X10: =L10*K10 | Y10: =M10*K10 | Z10: =N10*K10 | AA10: =O10*K10 | AB10: =P10*K10 | AC10: =Q10*K10 | AD10: =R10*K10 | AE10: =S10*K10 | AF10: =T10*K10 | AG10: =U10*K10 | AH10: =V10*K10 | AI10: =W10*K10
A11: 1043 | B11: =IF(A11="","",IFERROR(INDEX(Mitarbeiter!$B$6:$B$205,MATCH($A11,Mitarbeiter!$A$6:$A$205,0)),"?")) | C11: Objekt 2 | D11: 46035 | E11: 46036 | F11: =IF(A11="","",SUM(L11:W11)) | G11: =IF(A11="","",SUM(X11:AI11)) | H11: =IF(A11="","",IF(ISNA(MATCH(A11,Mitarbeiter!$A$6:$A$205,0)),"Pers.-Nr. unbekannt",IF(D11="","Von fehlt",IF(AND(C11<>Einstellungen!$C$4,C11<>Einstellungen!$C$5),"Objekt fehlt",IF(J11<D11,"Bis vor Von",IF(D11<INDEX(Mitarbeiter!$C$6:$C$205,MATCH($A11,Mitarbeiter!$A$6:$A$205,0)),"vor Eintritt",IF(AND(INDEX(Mitarbeiter!$D$6:$D$205,MATCH($A11,Mitarbeiter!$A$6:$A$205,0))<>"",D11>INDEX(Mitarbeiter!$D$6:$D$205,MATCH($A11,Mitarbeiter!$A$6:$A$205,0))),"nach Austritt",IF(E11="","offen","ok")))))))) | J11: =IF(A11="","",IF(E11="",Einstellungen!$C$9,E11)) | K11: =IF(A11="",0,IFERROR(INDEX(Mitarbeiter!$F$6:$F$205,MATCH($A11,Mitarbeiter!$A$6:$A$205,0)),0)) | L11: =IF(OR(A11="",D11=""),0,MAX(0,NETWORKDAYS(MAX(D11,DATE(Einstellungen!$C$3,1,1)),MIN(J11,DATE(Einstellungen!$C$3,2,0)),Einstellungen!$F$13:$F$32))) | M11: =IF(OR(A11="",D11=""),0,MAX(0,NETWORKDAYS(MAX(D11,DATE(Einstellungen!$C$3,2,1)),MIN(J11,DATE(Einstellungen!$C$3,3,0)),Einstellungen!$F$13:$F$32))) | N11: =IF(OR(A11="",D11=""),0,MAX(0,NETWORKDAYS(MAX(D11,DATE(Einstellungen!$C$3,3,1)),MIN(J11,DATE(Einstellungen!$C$3,4,0)),Einstellungen!$F$13:$F$32))) | O11: =IF(OR(A11="",D11=""),0,MAX(0,NETWORKDAYS(MAX(D11,DATE(Einstellungen!$C$3,4,1)),MIN(J11,DATE(Einstellungen!$C$3,5,0)),Einstellungen!$F$13:$F$32))) | P11: =IF(OR(A11="",D11=""),0,MAX(0,NETWORKDAYS(MAX(D11,DATE(Einstellungen!$C$3,5,1)),MIN(J11,DATE(Einstellungen!$C$3,6,0)),Einstellungen!$F$13:$F$32))) | Q11: =IF(OR(A11="",D11=""),0,MAX(0,NETWORKDAYS(MAX(D11,DATE(Einstellungen!$C$3,6,1)),MIN(J11,DATE(Einstellungen!$C$3,7,0)),Einstellungen!$F$13:$F$32))) | R11: =IF(OR(A11="",D11=""),0,MAX(0,NETWORKDAYS(MAX(D11,DATE(Einstellungen!$C$3,7,1)),MIN(J11,DATE(Einstellungen!$C$3,8,0)),Einstellungen!$F$13:$F$32))) | S11: =IF(OR(A11="",D11=""),0,MAX(0,NETWORKDAYS(MAX(D11,DATE(Einstellungen!$C$3,8,1)),MIN(J11,DATE(Einstellungen!$C$3,9,0)),Einstellungen!$F$13:$F$32))) | T11: =IF(OR(A11="",D11=""),0,MAX(0,NETWORKDAYS(MAX(D11,DATE(Einstellungen!$C$3,9,1)),MIN(J11,DATE(Einstellungen!$C$3,10,0)),Einstellungen!$F$13:$F$32))) | U11: =IF(OR(A11="",D11=""),0,MAX(0,NETWORKDAYS(MAX(D11,DATE(Einstellungen!$C$3,10,1)),MIN(J11,DATE(Einstellungen!$C$3,11,0)),Einstellungen!$F$13:$F$32))) | V11: =IF(OR(A11="",D11=""),0,MAX(0,NETWORKDAYS(MAX(D11,DATE(Einstellungen!$C$3,11,1)),MIN(J11,DATE(Einstellungen!$C$3,12,0)),Einstellungen!$F$13:$F$32))) | W11: =IF(OR(A11="",D11=""),0,MAX(0,NETWORKDAYS(MAX(D11,DATE(Einstellungen!$C$3,12,1)),MIN(J11,DATE(Einstellungen!$C$3,13,0)),Einstellungen!$F$13:$F$32))) | X11: =L11*K11 | Y11: =M11*K11 | Z11: =N11*K11 | AA11: =O11*K11 | AB11: =P11*K11 | AC11: =Q11*K11 | AD11: =R11*K11 | AE11: =S11*K11 | AF11: =T11*K11 | AG11: =U11*K11 | AH11: =V11*K11 | AI11: =W11*K11
A12: 1036 | B12: =IF(A12="","",IFERROR(INDEX(Mitarbeiter!$B$6:$B$205,MATCH($A12,Mitarbeiter!$A$6:$A$205,0)),"?")) | C12: Objekt 2 | D12: 46036 | E12: 46056 | F12: =IF(A12="","",SUM(L12:W12)) | G12: =IF(A12="","",SUM(X12:AI12)) | H12: =IF(A12="","",IF(ISNA(MATCH(A12,Mitarbeiter!$A$6:$A$205,0)),"Pers.-Nr. unbekannt",IF(D12="","Von fehlt",IF(AND(C12<>Einstellungen!$C$4,C12<>Einstellungen!$C$5),"Objekt fehlt",IF(J12<D12,"Bis vor Von",IF(D12<INDEX(Mitarbeiter!$C$6:$C$205,MATCH($A12,Mitarbeiter!$A$6:$A$205,0)),"vor Eintritt",IF(AND(INDEX(Mitarbeiter!$D$6:$D$205,MATCH($A12,Mitarbeiter!$A$6:$A$205,0))<>"",D12>INDEX(Mitarbeiter!$D$6:$D$205,MATCH($A12,Mitarbeiter!$A$6:$A$205,0))),"nach Austritt",IF(E12="","offen","ok")))))))) | J12: =IF(A12="","",IF(E12="",Einstellungen!$C$9,E12)) | K12: =IF(A12="",0,IFERROR(INDEX(Mitarbeiter!$F$6:$F$205,MATCH($A12,Mitarbeiter!$A$6:$A$205,0)),0)) | L12: =IF(OR(A12="",D12=""),0,MAX(0,NETWORKDAYS(MAX(D12,DATE(Einstellungen!$C$3,1,1)),MIN(J12,DATE(Einstellungen!$C$3,2,0)),Einstellungen!$F$13:$F$32))) | M12: =IF(OR(A12="",D12=""),0,MAX(0,NETWORKDAYS(MAX(D12,DATE(Einstellungen!$C$3,2,1)),MIN(J12,DATE(Einstellungen!$C$3,3,0)),Einstellungen!$F$13:$F$32))) | N12: =IF(OR(A12="",D12=""),0,MAX(0,NETWORKDAYS(MAX(D12,DATE(Einstellungen!$C$3,3,1)),MIN(J12,DATE(Einstellungen!$C$3,4,0)),Einstellungen!$F$13:$F$32))) | O12: =IF(OR(A12="",D12=""),0,MAX(0,NETWORKDAYS(MAX(D12,DATE(Einstellungen!$C$3,4,1)),MIN(J12,DATE(Einstellungen!$C$3,5,0)),Einstellungen!$F$13:$F$32))) | P12: =IF(OR(A12="",D12=""),0,MAX(0,NETWORKDAYS(MAX(D12,DATE(Einstellungen!$C$3,5,1)),MIN(J12,DATE(Einstellungen!$C$3,6,0)),Einstellungen!$F$13:$F$32))) | Q12: =IF(OR(A12="",D12=""),0,MAX(0,NETWORKDAYS(MAX(D12,DATE(Einstellungen!$C$3,6,1)),MIN(J12,DATE(Einstellungen!$C$3,7,0)),Einstellungen!$F$13:$F$32))) | R12: =IF(OR(A12="",D12=""),0,MAX(0,NETWORKDAYS(MAX(D12,DATE(Einstellungen!$C$3,7,1)),MIN(J12,DATE(Einstellungen!$C$3,8,0)),Einstellungen!$F$13:$F$32))) | S12: =IF(OR(A12="",D12=""),0,MAX(0,NETWORKDAYS(MAX(D12,DATE(Einstellungen!$C$3,8,1)),MIN(J12,DATE(Einstellungen!$C$3,9,0)),Einstellungen!$F$13:$F$32))) | T12: =IF(OR(A12="",D12=""),0,MAX(0,NETWORKDAYS(MAX(D12,DATE(Einstellungen!$C$3,9,1)),MIN(J12,DATE(Einstellungen!$C$3,10,0)),Einstellungen!$F$13:$F$32))) | U12: =IF(OR(A12="",D12=""),0,MAX(0,NETWORKDAYS(MAX(D12,DATE(Einstellungen!$C$3,10,1)),MIN(J12,DATE(Einstellungen!$C$3,11,0)),Einstellungen!$F$13:$F$32))) | V12: =IF(OR(A12="",D12=""),0,MAX(0,NETWORKDAYS(MAX(D12,DATE(Einstellungen!$C$3,11,1)),MIN(J12,DATE(Einstellungen!$C$3,12,0)),Einstellungen!$F$13:$F$32))) | W12: =IF(OR(A12="",D12=""),0,MAX(0,NETWORKDAYS(MAX(D12,DATE(Einstellungen!$C$3,12,1)),MIN(J12,DATE(Einstellungen!$C$3,13,0)),Einstellungen!$F$13:$F$32))) | X12: =L12*K12 | Y12: =M12*K12 | Z12: =N12*K12 | AA12: =O12*K12 | AB12: =P12*K12 | AC12: =Q12*K12 | AD12: =R12*K12 | AE12: =S12*K12 | AF12: =T12*K12 | AG12: =U12*K12 | AH12: =V12*K12 | AI12: =W12*K12
A13: 1009 | B13: =IF(A13="","",IFERROR(INDEX(Mitarbeiter!$B$6:$B$205,MATCH($A13,Mitarbeiter!$A$6:$A$205,0)),"?")) | C13: Objekt 2 | D13: 46036 | E13: 46037 | F13: =IF(A13="","",SUM(L13:W13)) | G13: =IF(A13="","",SUM(X13:AI13)) | H13: =IF(A13="","",IF(ISNA(MATCH(A13,Mitarbeiter!$A$6:$A$205,0)),"Pers.-Nr. unbekannt",IF(D13="","Von fehlt",IF(AND(C13<>Einstellungen!$C$4,C13<>Einstellungen!$C$5),"Objekt fehlt",IF(J13<D13,"Bis vor Von",IF(D13<INDEX(Mitarbeiter!$C$6:$C$205,MATCH($A13,Mitarbeiter!$A$6:$A$205,0)),"vor Eintritt",IF(AND(INDEX(Mitarbeiter!$D$6:$D$205,MATCH($A13,Mitarbeiter!$A$6:$A$205,0))<>"",D13>INDEX(Mitarbeiter!$D$6:$D$205,MATCH($A13,Mitarbeiter!$A$6:$A$205,0))),"nach Austritt",IF(E13="","offen","ok")))))))) | J13: =IF(A13="","",IF(E13="",Einstellungen!$C$9,E13)) | K13: =IF(A13="",0,IFERROR(INDEX(Mitarbeiter!$F$6:$F$205,MATCH($A13,Mitarbeiter!$A$6:$A$205,0)),0)) | L13: =IF(OR(A13="",D13=""),0,MAX(0,NETWORKDAYS(MAX(D13,DATE(Einstellungen!$C$3,1,1)),MIN(J13,DATE(Einstellungen!$C$3,2,0)),Einstellungen!$F$13:$F$32))) | M13: =IF(OR(A13="",D13=""),0,MAX(0,NETWORKDAYS(MAX(D13,DATE(Einstellungen!$C$3,2,1)),MIN(J13,DATE(Einstellungen!$C$3,3,0)),Einstellungen!$F$13:$F$32))) | N13: =IF(OR(A13="",D13=""),0,MAX(0,NETWORKDAYS(MAX(D13,DATE(Einstellungen!$C$3,3,1)),MIN(J13,DATE(Einstellungen!$C$3,4,0)),Einstellungen!$F$13:$F$32))) | O13: =IF(OR(A13="",D13=""),0,MAX(0,NETWORKDAYS(MAX(D13,DATE(Einstellungen!$C$3,4,1)),MIN(J13,DATE(Einstellungen!$C$3,5,0)),Einstellungen!$F$13:$F$32))) | P13: =IF(OR(A13="",D13=""),0,MAX(0,NETWORKDAYS(MAX(D13,DATE(Einstellungen!$C$3,5,1)),MIN(J13,DATE(Einstellungen!$C$3,6,0)),Einstellungen!$F$13:$F$32))) | Q13: =IF(OR(A13="",D13=""),0,MAX(0,NETWORKDAYS(MAX(D13,DATE(Einstellungen!$C$3,6,1)),MIN(J13,DATE(Einstellungen!$C$3,7,0)),Einstellungen!$F$13:$F$32))) | R13: =IF(OR(A13="",D13=""),0,MAX(0,NETWORKDAYS(MAX(D13,DATE(Einstellungen!$C$3,7,1)),MIN(J13,DATE(Einstellungen!$C$3,8,0)),Einstellungen!$F$13:$F$32))) | S13: =IF(OR(A13="",D13=""),0,MAX(0,NETWORKDAYS(MAX(D13,DATE(Einstellungen!$C$3,8,1)),MIN(J13,DATE(Einstellungen!$C$3,9,0)),Einstellungen!$F$13:$F$32))) | T13: =IF(OR(A13="",D13=""),0,MAX(0,NETWORKDAYS(MAX(D13,DATE(Einstellungen!$C$3,9,1)),MIN(J13,DATE(Einstellungen!$C$3,10,0)),Einstellungen!$F$13:$F$32))) | U13: =IF(OR(A13="",D13=""),0,MAX(0,NETWORKDAYS(MAX(D13,DATE(Einstellungen!$C$3,10,1)),MIN(J13,DATE(Einstellungen!$C$3,11,0)),Einstellungen!$F$13:$F$32))) | V13: =IF(OR(A13="",D13=""),0,MAX(0,NETWORKDAYS(MAX(D13,DATE(Einstellungen!$C$3,11,1)),MIN(J13,DATE(Einstellungen!$C$3,12,0)),Einstellungen!$F$13:$F$32))) | W13: =IF(OR(A13="",D13=""),0,MAX(0,NETWORKDAYS(MAX(D13,DATE(Einstellungen!$C$3,12,1)),MIN(J13,DATE(Einstellungen!$C$3,13,0)),Einstellungen!$F$13:$F$32))) | X13: =L13*K13 | Y13: =M13*K13 | Z13: =N13*K13 | AA13: =O13*K13 | AB13: =P13*K13 | AC13: =Q13*K13 | AD13: =R13*K13 | AE13: =S13*K13 | AF13: =T13*K13 | AG13: =U13*K13 | AH13: =V13*K13 | AI13: =W13*K13
A14: 1014 | B14: =IF(A14="","",IFERROR(INDEX(Mitarbeiter!$B$6:$B$205,MATCH($A14,Mitarbeiter!$A$6:$A$205,0)),"?")) | C14: Objekt 2 | D14: 46037 | E14: 46043 | F14: =IF(A14="","",SUM(L14:W14)) | G14: =IF(A14="","",SUM(X14:AI14)) | H14: =IF(A14="","",IF(ISNA(MATCH(A14,Mitarbeiter!$A$6:$A$205,0)),"Pers.-Nr. unbekannt",IF(D14="","Von fehlt",IF(AND(C14<>Einstellungen!$C$4,C14<>Einstellungen!$C$5),"Objekt fehlt",IF(J14<D14,"Bis vor Von",IF(D14<INDEX(Mitarbeiter!$C$6:$C$205,MATCH($A14,Mitarbeiter!$A$6:$A$205,0)),"vor Eintritt",IF(AND(INDEX(Mitarbeiter!$D$6:$D$205,MATCH($A14,Mitarbeiter!$A$6:$A$205,0))<>"",D14>INDEX(Mitarbeiter!$D$6:$D$205,MATCH($A14,Mitarbeiter!$A$6:$A$205,0))),"nach Austritt",IF(E14="","offen","ok")))))))) | J14: =IF(A14="","",IF(E14="",Einstellungen!$C$9,E14)) | K14: =IF(A14="",0,IFERROR(INDEX(Mitarbeiter!$F$6:$F$205,MATCH($A14,Mitarbeiter!$A$6:$A$205,0)),0)) | L14: =IF(OR(A14="",D14=""),0,MAX(0,NETWORKDAYS(MAX(D14,DATE(Einstellungen!$C$3,1,1)),MIN(J14,DATE(Einstellungen!$C$3,2,0)),Einstellungen!$F$13:$F$32))) | M14: =IF(OR(A14="",D14=""),0,MAX(0,NETWORKDAYS(MAX(D14,DATE(Einstellungen!$C$3,2,1)),MIN(J14,DATE(Einstellungen!$C$3,3,0)),Einstellungen!$F$13:$F$32))) | N14: =IF(OR(A14="",D14=""),0,MAX(0,NETWORKDAYS(MAX(D14,DATE(Einstellungen!$C$3,3,1)),MIN(J14,DATE(Einstellungen!$C$3,4,0)),Einstellungen!$F$13:$F$32))) | O14: =IF(OR(A14="",D14=""),0,MAX(0,NETWORKDAYS(MAX(D14,DATE(Einstellungen!$C$3,4,1)),MIN(J14,DATE(Einstellungen!$C$3,5,0)),Einstellungen!$F$13:$F$32))) | P14: =IF(OR(A14="",D14=""),0,MAX(0,NETWORKDAYS(MAX(D14,DATE(Einstellungen!$C$3,5,1)),MIN(J14,DATE(Einstellungen!$C$3,6,0)),Einstellungen!$F$13:$F$32))) | Q14: =IF(OR(A14="",D14=""),0,MAX(0,NETWORKDAYS(MAX(D14,DATE(Einstellungen!$C$3,6,1)),MIN(J14,DATE(Einstellungen!$C$3,7,0)),Einstellungen!$F$13:$F$32))) | R14: =IF(OR(A14="",D14=""),0,MAX(0,NETWORKDAYS(MAX(D14,DATE(Einstellungen!$C$3,7,1)),MIN(J14,DATE(Einstellungen!$C$3,8,0)),Einstellungen!$F$13:$F$32))) | S14: =IF(OR(A14="",D14=""),0,MAX(0,NETWORKDAYS(MAX(D14,DATE(Einstellungen!$C$3,8,1)),MIN(J14,DATE(Einstellungen!$C$3,9,0)),Einstellungen!$F$13:$F$32))) | T14: =IF(OR(A14="",D14=""),0,MAX(0,NETWORKDAYS(MAX(D14,DATE(Einstellungen!$C$3,9,1)),MIN(J14,DATE(Einstellungen!$C$3,10,0)),Einstellungen!$F$13:$F$32))) | U14: =IF(OR(A14="",D14=""),0,MAX(0,NETWORKDAYS(MAX(D14,DATE(Einstellungen!$C$3,10,1)),MIN(J14,DATE(Einstellungen!$C$3,11,0)),Einstellungen!$F$13:$F$32))) | V14: =IF(OR(A14="",D14=""),0,MAX(0,NETWORKDAYS(MAX(D14,DATE(Einstellungen!$C$3,11,1)),MIN(J14,DATE(Einstellungen!$C$3,12,0)),Einstellungen!$F$13:$F$32))) | W14: =IF(OR(A14="",D14=""),0,MAX(0,NETWORKDAYS(MAX(D14,DATE(Einstellungen!$C$3,12,1)),MIN(J14,DATE(Einstellungen!$C$3,13,0)),Einstellungen!$F$13:$F$32))) | X14: =L14*K14 | Y14: =M14*K14 | Z14: =N14*K14 | AA14: =O14*K14 | AB14: =P14*K14 | AC14: =Q14*K14 | AD14: =R14*K14 | AE14: =S14*K14 | AF14: =T14*K14 | AG14: =U14*K14 | AH14: =V14*K14 | AI14: =W14*K14
A15: 1037 | B15: =IF(A15="","",IFERROR(INDEX(Mitarbeiter!$B$6:$B$205,MATCH($A15,Mitarbeiter!$A$6:$A$205,0)),"?")) | C15: Objekt 1 | D15: 46037 | E15: 46039 | F15: =IF(A15="","",SUM(L15:W15)) | G15: =IF(A15="","",SUM(X15:AI15)) | H15: =IF(A15="","",IF(ISNA(MATCH(A15,Mitarbeiter!$A$6:$A$205,0)),"Pers.-Nr. unbekannt",IF(D15="","Von fehlt",IF(AND(C15<>Einstellungen!$C$4,C15<>Einstellungen!$C$5),"Objekt fehlt",IF(J15<D15,"Bis vor Von",IF(D15<INDEX(Mitarbeiter!$C$6:$C$205,MATCH($A15,Mitarbeiter!$A$6:$A$205,0)),"vor Eintritt",IF(AND(INDEX(Mitarbeiter!$D$6:$D$205,MATCH($A15,Mitarbeiter!$A$6:$A$205,0))<>"",D15>INDEX(Mitarbeiter!$D$6:$D$205,MATCH($A15,Mitarbeiter!$A$6:$A$205,0))),"nach Austritt",IF(E15="","offen","ok")))))))) | J15: =IF(A15="","",IF(E15="",Einstellungen!$C$9,E15)) | K15: =IF(A15="",0,IFERROR(INDEX(Mitarbeiter!$F$6:$F$205,MATCH($A15,Mitarbeiter!$A$6:$A$205,0)),0)) | L15: =IF(OR(A15="",D15=""),0,MAX(0,NETWORKDAYS(MAX(D15,DATE(Einstellungen!$C$3,1,1)),MIN(J15,DATE(Einstellungen!$C$3,2,0)),Einstellungen!$F$13:$F$32))) | M15: =IF(OR(A15="",D15=""),0,MAX(0,NETWORKDAYS(MAX(D15,DATE(Einstellungen!$C$3,2,1)),MIN(J15,DATE(Einstellungen!$C$3,3,0)),Einstellungen!$F$13:$F$32))) | N15: =IF(OR(A15="",D15=""),0,MAX(0,NETWORKDAYS(MAX(D15,DATE(Einstellungen!$C$3,3,1)),MIN(J15,DATE(Einstellungen!$C$3,4,0)),Einstellungen!$F$13:$F$32))) | O15: =IF(OR(A15="",D15=""),0,MAX(0,NETWORKDAYS(MAX(D15,DATE(Einstellungen!$C$3,4,1)),MIN(J15,DATE(Einstellungen!$C$3,5,0)),Einstellungen!$F$13:$F$32))) | P15: =IF(OR(A15="",D15=""),0,MAX(0,NETWORKDAYS(MAX(D15,DATE(Einstellungen!$C$3,5,1)),MIN(J15,DATE(Einstellungen!$C$3,6,0)),Einstellungen!$F$13:$F$32))) | Q15: =IF(OR(A15="",D15=""),0,MAX(0,NETWORKDAYS(MAX(D15,DATE(Einstellungen!$C$3,6,1)),MIN(J15,DATE(Einstellungen!$C$3,7,0)),Einstellungen!$F$13:$F$32))) | R15: =IF(OR(A15="",D15=""),0,MAX(0,NETWORKDAYS(MAX(D15,DATE(Einstellungen!$C$3,7,1)),MIN(J15,DATE(Einstellungen!$C$3,8,0)),Einstellungen!$F$13:$F$32))) | S15: =IF(OR(A15="",D15=""),0,MAX(0,NETWORKDAYS(MAX(D15,DATE(Einstellungen!$C$3,8,1)),MIN(J15,DATE(Einstellungen!$C$3,9,0)),Einstellungen!$F$13:$F$32))) | T15: =IF(OR(A15="",D15=""),0,MAX(0,NETWORKDAYS(MAX(D15,DATE(Einstellungen!$C$3,9,1)),MIN(J15,DATE(Einstellungen!$C$3,10,0)),Einstellungen!$F$13:$F$32))) | U15: =IF(OR(A15="",D15=""),0,MAX(0,NETWORKDAYS(MAX(D15,DATE(Einstellungen!$C$3,10,1)),MIN(J15,DATE(Einstellungen!$C$3,11,0)),Einstellungen!$F$13:$F$32))) | V15: =IF(OR(A15="",D15=""),0,MAX(0,NETWORKDAYS(MAX(D15,DATE(Einstellungen!$C$3,11,1)),MIN(J15,DATE(Einstellungen!$C$3,12,0)),Einstellungen!$F$13:$F$32))) | W15: =IF(OR(A15="",D15=""),0,MAX(0,NETWORKDAYS(MAX(D15,DATE(Einstellungen!$C$3,12,1)),MIN(J15,DATE(Einstellungen!$C$3,13,0)),Einstellungen!$F$13:$F$32))) | X15: =L15*K15 | Y15: =M15*K15 | Z15: =N15*K15 | AA15: =O15*K15 | AB15: =P15*K15 | AC15: =Q15*K15 | AD15: =R15*K15 | AE15: =S15*K15 | AF15: =T15*K15 | AG15: =U15*K15 | AH15: =V15*K15 | AI15: =W15*K15
A16: 1012 | B16: =IF(A16="","",IFERROR(INDEX(Mitarbeiter!$B$6:$B$205,MATCH($A16,Mitarbeiter!$A$6:$A$205,0)),"?")) | C16: Objekt 2 | D16: 46038 | E16: 46042 | F16: =IF(A16="","",SUM(L16:W16)) | G16: =IF(A16="","",SUM(X16:AI16)) | H16: =IF(A16="","",IF(ISNA(MATCH(A16,Mitarbeiter!$A$6:$A$205,0)),"Pers.-Nr. unbekannt",IF(D16="","Von fehlt",IF(AND(C16<>Einstellungen!$C$4,C16<>Einstellungen!$C$5),"Objekt fehlt",IF(J16<D16,"Bis vor Von",IF(D16<INDEX(Mitarbeiter!$C$6:$C$205,MATCH($A16,Mitarbeiter!$A$6:$A$205,0)),"vor Eintritt",IF(AND(INDEX(Mitarbeiter!$D$6:$D$205,MATCH($A16,Mitarbeiter!$A$6:$A$205,0))<>"",D16>INDEX(Mitarbeiter!$D$6:$D$205,MATCH($A16,Mitarbeiter!$A$6:$A$205,0))),"nach Austritt",IF(E16="","offen","ok")))))))) | J16: =IF(A16="","",IF(E16="",Einstellungen!$C$9,E16)) | K16: =IF(A16="",0,IFERROR(INDEX(Mitarbeiter!$F$6:$F$205,MATCH($A16,Mitarbeiter!$A$6:$A$205,0)),0)) | L16: =IF(OR(A16="",D16=""),0,MAX(0,NETWORKDAYS(MAX(D16,DATE(Einstellungen!$C$3,1,1)),MIN(J16,DATE(Einstellungen!$C$3,2,0)),Einstellungen!$F$13:$F$32))) | M16: =IF(OR(A16="",D16=""),0,MAX(0,NETWORKDAYS(MAX(D16,DATE(Einstellungen!$C$3,2,1)),MIN(J16,DATE(Einstellungen!$C$3,3,0)),Einstellungen!$F$13:$F$32))) | N16: =IF(OR(A16="",D16=""),0,MAX(0,NETWORKDAYS(MAX(D16,DATE(Einstellungen!$C$3,3,1)),MIN(J16,DATE(Einstellungen!$C$3,4,0)),Einstellungen!$F$13:$F$32))) | O16: =IF(OR(A16="",D16=""),0,MAX(0,NETWORKDAYS(MAX(D16,DATE(Einstellungen!$C$3,4,1)),MIN(J16,DATE(Einstellungen!$C$3,5,0)),Einstellungen!$F$13:$F$32))) | P16: =IF(OR(A16="",D16=""),0,MAX(0,NETWORKDAYS(MAX(D16,DATE(Einstellungen!$C$3,5,1)),MIN(J16,DATE(Einstellungen!$C$3,6,0)),Einstellungen!$F$13:$F$32))) | Q16: =IF(OR(A16="",D16=""),0,MAX(0,NETWORKDAYS(MAX(D16,DATE(Einstellungen!$C$3,6,1)),MIN(J16,DATE(Einstellungen!$C$3,7,0)),Einstellungen!$F$13:$F$32))) | R16: =IF(OR(A16="",D16=""),0,MAX(0,NETWORKDAYS(MAX(D16,DATE(Einstellungen!$C$3,7,1)),MIN(J16,DATE(Einstellungen!$C$3,8,0)),Einstellungen!$F$13:$F$32))) | S16: =IF(OR(A16="",D16=""),0,MAX(0,NETWORKDAYS(MAX(D16,DATE(Einstellungen!$C$3,8,1)),MIN(J16,DATE(Einstellungen!$C$3,9,0)),Einstellungen!$F$13:$F$32))) | T16: =IF(OR(A16="",D16=""),0,MAX(0,NETWORKDAYS(MAX(D16,DATE(Einstellungen!$C$3,9,1)),MIN(J16,DATE(Einstellungen!$C$3,10,0)),Einstellungen!$F$13:$F$32))) | U16: =IF(OR(A16="",D16=""),0,MAX(0,NETWORKDAYS(MAX(D16,DATE(Einstellungen!$C$3,10,1)),MIN(J16,DATE(Einstellungen!$C$3,11,0)),Einstellungen!$F$13:$F$32))) | V16: =IF(OR(A16="",D16=""),0,MAX(0,NETWORKDAYS(MAX(D16,DATE(Einstellungen!$C$3,11,1)),MIN(J16,DATE(Einstellungen!$C$3,12,0)),Einstellungen!$F$13:$F$32))) | W16: =IF(OR(A16="",D16=""),0,MAX(0,NETWORKDAYS(MAX(D16,DATE(Einstellungen!$C$3,12,1)),MIN(J16,DATE(Einstellungen!$C$3,13,0)),Einstellungen!$F$13:$F$32))) | X16: =L16*K16 | Y16: =M16*K16 | Z16: =N16*K16 | AA16: =O16*K16 | AB16: =P16*K16 | AC16: =Q16*K16 | AD16: =R16*K16 | AE16: =S16*K16 | AF16: =T16*K16 | AG16: =U16*K16 | AH16: =V16*K16 | AI16: =W16*K16
